2022-10-28 05:38:31.198 | ERROR    | hcaptcha_challenger._solutions.kernel:request_assets:142 - 0
2022-10-28 05:38:45.192 | ERROR    | hcaptcha_challenger._solutions.kernel:request_assets:142 - 0
2022-10-28 05:38:45.679 | ERROR    | services.scaffold:claim:138 - An error has been caught in function 'claim', process 'MainProcess' (1777), thread 'MainThread' (140013495158592):
Traceback (most recent call last):
  File "/home/runner/work/autogame/autogame/epic/src/main.py", line 11, in <module>
    Fire(Scaffold)
  File "/opt/hostedtoolcache/Python/3.10.8/x64/lib/python3.10/site-packages/fire/core.py", line 141, in Fire
    component_trace = _Fire(component, args, parsed_flag_args, context, name)
  File "/opt/hostedtoolcache/Python/3.10.8/x64/lib/python3.10/site-packages/fire/core.py", line 466, in _Fire
    component, remaining_args = _CallAndUpdateTrace(
  File "/opt/hostedtoolcache/Python/3.10.8/x64/lib/python3.10/site-packages/fire/core.py", line 681, in _CallAndUpdateTrace
    component = fn(*varargs, **kwargs)
> File "/home/runner/work/autogame/autogame/epic/src/services/scaffold.py", line 138, in claim
    claimer.run(silence=silence, log_ignore=ignore, unreal=unreal)
  File "/home/runner/work/autogame/autogame/epic/src/apis/scaffold/claimer.py", line 26, in run
    ClaimerScheduler(silence=silence, unreal=unreal).job_loop_claim(log_ignore)
  File "/home/runner/work/autogame/autogame/epic/src/services/deploy.py", line 113, in job_loop_claim
    with GameClaimerInstance(self.silence, log_ignore=log_ignore) as claimer:
  File "/home/runner/work/autogame/autogame/epic/src/services/deploy.py", line 166, in __enter__
    fire(
  File "/home/runner/work/autogame/autogame/epic/src/services/utils/toolbox.py", line 75, in fire
    container(context)
  File "/home/runner/work/autogame/autogame/epic/src/services/bricklayer/core.py", line 693, in refresh_ctx_cookies
    resp = self.armor.anti_hcaptcha(page, window="login", recur_url=recur_url)
  File "/home/runner/work/autogame/autogame/epic/src/services/bricklayer/core.py", line 258, in anti_hcaptcha
    self.challenge(frame_challenge, model=model)
  File "/home/runner/work/autogame/autogame/epic/src/services/bricklayer/core.py", line 125, in challenge
    result = model.solution(img_stream=data, label=self.label_alias[self.label])
  File "/opt/hostedtoolcache/Python/3.10.8/x64/lib/python3.10/site-packages/hcaptcha_challenger/_solutions/resnet.py", line 63, in solution
    return self.classifier(img_stream, feature_filters=None)
  File "/opt/hostedtoolcache/Python/3.10.8/x64/lib/python3.10/site-packages/hcaptcha_challenger/_solutions/resnet.py", line 54, in classifier
    raise ResourceWarning(_err_prompt)  # maybe mercy
ResourceWarning: 
            The remote network does not exist or the local cache has expired.
            1. Check objects.yaml for typos | model=octopus.onnx;
            2. Restart the program after deleting the local cache | dir=datas/models/_assets;
            
2022-12-20 20:46:10.405 | ERROR    | hcaptcha_challenger._solutions.kernel:request_assets:157 - 0
2022-12-20 20:46:41.101 | ERROR    | hcaptcha_challenger._solutions.kernel:request_assets:157 - 0
2022-12-20 20:46:41.251 | ERROR    | services.scaffold:claim:138 - An error has been caught in function 'claim', process 'MainProcess' (1838), thread 'MainThread' (139945960234048):
Traceback (most recent call last):
  File "/home/runner/work/autogame/autogame/epic/src/main.py", line 11, in <module>
    Fire(Scaffold)
  File "/opt/hostedtoolcache/Python/3.10.9/x64/lib/python3.10/site-packages/fire/core.py", line 141, in Fire
    component_trace = _Fire(component, args, parsed_flag_args, context, name)
  File "/opt/hostedtoolcache/Python/3.10.9/x64/lib/python3.10/site-packages/fire/core.py", line 466, in _Fire
    component, remaining_args = _CallAndUpdateTrace(
  File "/opt/hostedtoolcache/Python/3.10.9/x64/lib/python3.10/site-packages/fire/core.py", line 681, in _CallAndUpdateTrace
    component = fn(*varargs, **kwargs)
> File "/home/runner/work/autogame/autogame/epic/src/services/scaffold.py", line 138, in claim
    claimer.run(silence=silence, log_ignore=ignore, unreal=unreal)
  File "/home/runner/work/autogame/autogame/epic/src/apis/scaffold/claimer.py", line 26, in run
    ClaimerScheduler(silence=silence, unreal=unreal).job_loop_claim(log_ignore)
  File "/home/runner/work/autogame/autogame/epic/src/services/deploy.py", line 112, in job_loop_claim
    claimer.just_do_it()
  File "/home/runner/work/autogame/autogame/epic/src/services/deploy.py", line 309, in just_do_it
    fire(
  File "/home/runner/work/autogame/autogame/epic/src/services/utils/toolbox.py", line 84, in fire
    container(context)
  File "/home/runner/work/autogame/autogame/epic/src/services/deploy.py", line 305, in run
    result = empower_games_claimer(self.bricklayer, promotion.url, page, pattern="get")
  File "/home/runner/work/autogame/autogame/epic/src/services/bricklayer/game.py", line 170, in empower_games_claimer
    return claimer.get_free_game(page_link=page_link, page=page, pattern=pattern)
  File "/home/runner/work/autogame/autogame/epic/src/services/bricklayer/game.py", line 157, in get_free_game
    self.cart_handle_payment(page)  # mode: get
  File "/home/runner/work/autogame/autogame/epic/src/services/bricklayer/core.py", line 561, in cart_handle_payment
    self._duel_with_challenge(page)  # cart_handle_payment
  File "/home/runner/work/autogame/autogame/epic/src/services/bricklayer/core.py", line 474, in _duel_with_challenge
    resp = self.armor.anti_hcaptcha(page, window=window)
  File "/home/runner/work/autogame/autogame/epic/src/services/bricklayer/core.py", line 267, in anti_hcaptcha
    self.challenge(frame_challenge, model=model)
  File "/home/runner/work/autogame/autogame/epic/src/services/bricklayer/core.py", line 125, in challenge
    result = model.solution(img_stream=data, label=self.label_alias[self.label])
  File "/opt/hostedtoolcache/Python/3.10.9/x64/lib/python3.10/site-packages/hcaptcha_challenger/_solutions/resnet.py", line 63, in solution
    return self.classifier(img_stream, feature_filters=None)
  File "/opt/hostedtoolcache/Python/3.10.9/x64/lib/python3.10/site-packages/hcaptcha_challenger/_solutions/resnet.py", line 54, in classifier
    raise ResourceWarning(_err_prompt)  # maybe mercy
ResourceWarning: 
            The remote network does not exist or the local cache has expired.
            1. Check objects.yaml for typos | model=tulip.onnx;
            2. Restart the program after deleting the local cache | dir=datas/models/_assets;
            
2022-12-30 05:33:26.646 | ERROR    | hcaptcha_challenger._solutions.kernel:request_assets:157 - 0
2022-12-30 05:33:58.962 | ERROR    | hcaptcha_challenger._solutions.kernel:request_assets:157 - 0
2022-12-30 05:33:59.205 | ERROR    | services.scaffold:claim:138 - An error has been caught in function 'claim', process 'MainProcess' (1958), thread 'MainThread' (139882868112448):
Traceback (most recent call last):
  File "/home/runner/work/autogame/autogame/epic/src/main.py", line 11, in <module>
    Fire(Scaffold)
  File "/opt/hostedtoolcache/Python/3.10.9/x64/lib/python3.10/site-packages/fire/core.py", line 141, in Fire
    component_trace = _Fire(component, args, parsed_flag_args, context, name)
  File "/opt/hostedtoolcache/Python/3.10.9/x64/lib/python3.10/site-packages/fire/core.py", line 466, in _Fire
    component, remaining_args = _CallAndUpdateTrace(
  File "/opt/hostedtoolcache/Python/3.10.9/x64/lib/python3.10/site-packages/fire/core.py", line 681, in _CallAndUpdateTrace
    component = fn(*varargs, **kwargs)
> File "/home/runner/work/autogame/autogame/epic/src/services/scaffold.py", line 138, in claim
    claimer.run(silence=silence, log_ignore=ignore, unreal=unreal)
  File "/home/runner/work/autogame/autogame/epic/src/apis/scaffold/claimer.py", line 26, in run
    ClaimerScheduler(silence=silence, unreal=unreal).job_loop_claim(log_ignore)
  File "/home/runner/work/autogame/autogame/epic/src/services/deploy.py", line 112, in job_loop_claim
    claimer.just_do_it()
  File "/home/runner/work/autogame/autogame/epic/src/services/deploy.py", line 309, in just_do_it
    fire(
  File "/home/runner/work/autogame/autogame/epic/src/services/utils/toolbox.py", line 84, in fire
    container(context)
  File "/home/runner/work/autogame/autogame/epic/src/services/deploy.py", line 305, in run
    result = empower_games_claimer(self.bricklayer, promotion.url, page, pattern="get")
  File "/home/runner/work/autogame/autogame/epic/src/services/bricklayer/game.py", line 170, in empower_games_claimer
    return claimer.get_free_game(page_link=page_link, page=page, pattern=pattern)
  File "/home/runner/work/autogame/autogame/epic/src/services/bricklayer/game.py", line 157, in get_free_game
    self.cart_handle_payment(page)  # mode: get
  File "/home/runner/work/autogame/autogame/epic/src/services/bricklayer/core.py", line 561, in cart_handle_payment
    self._duel_with_challenge(page)  # cart_handle_payment
  File "/home/runner/work/autogame/autogame/epic/src/services/bricklayer/core.py", line 474, in _duel_with_challenge
    resp = self.armor.anti_hcaptcha(page, window=window)
  File "/home/runner/work/autogame/autogame/epic/src/services/bricklayer/core.py", line 267, in anti_hcaptcha
    self.challenge(frame_challenge, model=model)
  File "/home/runner/work/autogame/autogame/epic/src/services/bricklayer/core.py", line 125, in challenge
    result = model.solution(img_stream=data, label=self.label_alias[self.label])
  File "/opt/hostedtoolcache/Python/3.10.9/x64/lib/python3.10/site-packages/hcaptcha_challenger/_solutions/resnet.py", line 63, in solution
    return self.classifier(img_stream, feature_filters=None)
  File "/opt/hostedtoolcache/Python/3.10.9/x64/lib/python3.10/site-packages/hcaptcha_challenger/_solutions/resnet.py", line 54, in classifier
    raise ResourceWarning(_err_prompt)  # maybe mercy
ResourceWarning: 
            The remote network does not exist or the local cache has expired.
            1. Check objects.yaml for typos | model=ladybug.onnx;
            2. Restart the program after deleting the local cache | dir=datas/models/_assets;
            
